<?xml version="1.0" encoding="UTF-8"?>
<robot xmlns:xacro="http://ros.org/wiki/xacro">
  <!-- constants -->
  <xacro:include
      filename="$(find mg400_description)/urdf/common/constants.xacro"
      ns="const" />

  <!-- Base path for meshes -->
  <xacro:property
      name="BASE_PATH"
      value="mg400_description/meshes" />
  <xacro:property
      name="MESH_BASE_LINK"
      value="${BASE_PATH}/base_link.dae" />
  <xacro:property
      name="MESH_LINK_1"
      value="${BASE_PATH}/link1.dae" />
  <xacro:property
      name="MESH_LINK_2_1"
      value="${BASE_PATH}/link2_1.dae" />
  <xacro:property
      name="MESH_LINK_2_2"
      value="${BASE_PATH}/link2_2.dae" />
  <xacro:property
      name="MESH_LINK_3_1"
      value="${BASE_PATH}/link3_1.dae" />
  <xacro:property
      name="MESH_LINK_3_2"
      value="${BASE_PATH}/link3_2.dae" />
  <xacro:property
      name="MESH_LINK_4_1"
      value="${BASE_PATH}/link4_1.dae" />
  <xacro:property
      name="MESH_LINK_4_2"
      value="${BASE_PATH}/link4_2.dae" />
  <xacro:property
      name="MESH_LINK_4_3"
      value="${BASE_PATH}/link4_3.dae" />
  <xacro:property
      name="MESH_LINK_5"
      value="${BASE_PATH}/link5.dae" />
  <xacro:property
      name="MESH_FLANGE"
      value="${BASE_PATH}/flange.dae" />
  <xacro:property
      name="MESH_WORKSPACE"
      value="${BASE_PATH}/workspace.dae" />

  <xacro:macro
      name="mg400"
      params="prefix parent *origin workspace_visible">
    <material name="${prefix}mg400_workspace_material">
      <color rgba="0.2 0.0 0.0 0.5" />
    </material>
    <!-- links -->
    <link name="${prefix}mg400_base_link">
      <inertial>
        <origin
            xyz="0.000600637001378879 -2.53487071137343E-07 0.0560927888040551"
            rpy="0 0 0" />
        <mass value="3.62164811695094" />
        <inertia
            ixx="0.0126582175296405"
            ixy="6.66832041405407E-08"
            ixz="-3.52548281362717E-06"
            iyy="0.0145891535260188"
            iyz="5.15901657460475E-08"
            izz="0.0195045116656827" />
      </inertial>
      <visual>
        <origin
            xyz="0 0 0"
            rpy="0 0 0" />
        <geometry>
          <mesh filename="package://${MESH_BASE_LINK}" />
        </geometry>
      </visual>
      <collision>
        <origin
            xyz="0 0 0"
            rpy="0 0 0" />
        <geometry>
          <mesh filename="package://${MESH_BASE_LINK}" />
        </geometry>
      </collision>
    </link>
    <link name="${prefix}mg400_origin_link" />
    <link name="${prefix}mg400_link1">
      <inertial>
        <origin
            xyz="-0.0046209286967387 -6.88107982318643E-05 0.0709919358465827"
            rpy="0 0 0" />
        <mass value="1.77056222753813" />
        <inertia
            ixx="0.00605885293080088"
            ixy="0.000156081820035162"
            ixz="-0.00021785654850453"
            iyy="0.00579381982249127"
            iyz="6.20876898015621E-05"
            izz="0.00741058257251941" />
      </inertial>
      <visual>
        <origin
            xyz="0 0 0"
            rpy="0 0 0" />
        <geometry>
          <mesh filename="package://${MESH_LINK_1}" />
        </geometry>
      </visual>
      <collision>
        <origin
            xyz="0 0 0"
            rpy="0 0 0" />
        <geometry>
          <mesh filename="package://${MESH_LINK_1}" />
        </geometry>
      </collision>
    </link>
    <link name="${prefix}mg400_link2_1">
      <inertial>
        <origin
            xyz="-0.00321788524756698 0.0352926570826593 0.0596131328734945"
            rpy="0 0 0" />
        <mass value="0.0866115884541459" />
        <inertia
            ixx="0.000338551627157209"
            ixy="-2.78858228577314E-09"
            ixz="1.05212346076681E-05"
            iyy="0.000307789653713489"
            iyz="-1.36109590152488E-06"
            izz="3.89949940178023E-05" />
      </inertial>
      <visual>
        <origin
            xyz="0 0 0"
            rpy="0 0 0" />
        <geometry>
          <mesh filename="package://${MESH_LINK_2_1}" />
        </geometry>
      </visual>
      <collision>
        <origin
            xyz="0 0 0"
            rpy="0 0 0" />
        <geometry>
          <mesh filename="package://${MESH_LINK_2_1}" />
        </geometry>
      </collision>
    </link>
    <link name="${prefix}mg400_link2_2">
      <inertial>
        <origin
            xyz="-0.0201111131723385 0.0304999635268521 0.073632809340276"
            rpy="0 0 0" />
        <mass value="0.0662546292985346" />
        <inertia
            ixx="0.000218973873589181"
            ixy="3.0147933007673E-10"
            ixz="2.51402553227571E-06"
            iyy="0.000200510070261609"
            iyz="-1.41837669904595E-09"
            izz="3.74316777806776E-05" />
      </inertial>
      <visual>
        <origin
            xyz="0 0 0"
            rpy="0 0 0" />
        <geometry>
          <mesh filename="package://${MESH_LINK_2_2}" />
        </geometry>
      </visual>
      <collision>
        <origin
            xyz="0 0 0"
            rpy="0 0 0" />
        <geometry>
          <mesh filename="package://${MESH_LINK_2_2}" />
        </geometry>
      </collision>
    </link>
    <link name="${prefix}mg400_link3_1">
      <inertial>
        <origin
            xyz="0.0821679417596488 0.000113044685842874 -0.00333758753063973"
            rpy="0 0 0" />
        <mass value="0.0375214831045061" />
        <inertia
            ixx="2.54761091812684E-06"
            ixy="3.73102654491378E-07"
            ixz="-2.02625705871199E-06"
            iyy="0.000164234314177935"
            iyz="-1.44731096825347E-08"
            izz="0.000164331500854172" />
      </inertial>
      <visual>
        <origin
            xyz="0 0 0"
            rpy="0 0 0" />
        <geometry>
          <mesh filename="package://${MESH_LINK_3_1}" />
        </geometry>
      </visual>
      <collision>
        <origin
            xyz="0 0 0"
            rpy="0 0 0" />
        <geometry>
          <mesh filename="package://${MESH_LINK_3_1}" />
        </geometry>
      </collision>
    </link>
    <link name="${prefix}mg400_link3_2">
      <inertial>
        <origin
            xyz="0.0338566736074436 0.0240208873857428 0.00452229895926692"
            rpy="0 0 0" />
        <mass value="0.0366692789294813" />
        <inertia
            ixx="7.24011830695354E-06"
            ixy="7.93542746250724E-10"
            ixz="-1.69163254472566E-06"
            iyy="2.34967008246727E-05"
            iyz="4.55507111386579E-10"
            izz="1.66831643179488E-05" />
      </inertial>
      <visual>
        <origin
            xyz="0 0 0"
            rpy="0 0 0" />
        <geometry>
          <mesh filename="package://${MESH_LINK_3_2}" />
        </geometry>
      </visual>
      <collision>
        <origin
            xyz="0 0 0"
            rpy="0 0 0" />
        <geometry>
          <mesh filename="package://${MESH_LINK_3_2}" />
        </geometry>
      </collision>
    </link>
    <link name="${prefix}mg400_link4_1">
      <inertial>
        <origin
            xyz="0.0387878182928232 0.0170848333998282 -0.0024610990490942"
            rpy="0 0 0" />
        <mass value="0.0628979533925801" />
        <inertia
            ixx="4.78483605712844E-05"
            ixy="1.42081909356751E-07"
            ixz="8.32917079044309E-06"
            iyy="5.42362047732042E-05"
            iyz="-2.90608446019989E-08"
            izz="3.36120409842199E-05" />
      </inertial>
      <visual>
        <origin
            xyz="0 0 0"
            rpy="0 0 0" />
        <geometry>
          <mesh filename="package://${MESH_LINK_4_1}" />
        </geometry>
      </visual>
      <collision>
        <origin
            xyz="0 0 0"
            rpy="0 0 0" />
        <geometry>
          <mesh filename="package://${MESH_LINK_4_1}" />
        </geometry>
      </collision>
    </link>
    <link name="${prefix}mg400_link4_2">
      <inertial>
        <origin
            xyz="0.0876391591012518 0.023499867452275 0.00831492252441945"
            rpy="0 0 0" />
        <mass value="0.0453569016333092" />
        <inertia
            ixx="2.00037596001325E-05"
            ixy="3.34474706250153E-09"
            ixz="2.17594982354756E-07"
            iyy="0.000132049841023893"
            iyz="5.36978669669685E-10"
            izz="0.000141813978894428" />
      </inertial>
      <visual>
        <origin
            xyz="0 0 0"
            rpy="0 0 0" />
        <geometry>
          <mesh filename="package://${MESH_LINK_4_2}" />
        </geometry>
      </visual>
      <collision>
        <origin
            xyz="0 0 0"
            rpy="0 0 0" />
        <geometry>
          <mesh filename="package://${MESH_LINK_4_2}" />
        </geometry>
      </collision>
    </link>
    <link name="${prefix}mg400_link4_3">
      <inertial>
        <origin
            xyz="${3.174 * const.SCALE_MM} 0.0 ${-28.198 * const.SCALE_MM}"
            rpy="0 0 0" />
        <mass value="0.01907" />
        <inertia
            ixx="3.28164E-05"
            ixy="3.15E-10"
            ixz="2.42378E-06"
            iyy="3.17191E-05"
            iyz="-1.27E-10"
            izz="1.08143E-05" />
      </inertial>
      <visual>
        <origin
            xyz="0 0 0"
            rpy="0 0 0" />
        <geometry>
          <mesh filename="package://${MESH_LINK_4_3}" />
        </geometry>
      </visual>
      <collision>
        <origin
            xyz="0 0 0"
            rpy="0 0 0" />
        <geometry>
          <mesh filename="package://${MESH_LINK_4_3}" />
        </geometry>
      </collision>
    </link>
    <link name="${prefix}mg400_link5">
      <inertial>
        <origin
            xyz="4.24246458685662E-07 3.08507851181768E-14 -0.0349688816440933"
            rpy="0 0 0" />
        <mass value="0.0965276919819365" />
        <inertia
            ixx="4.98589992160928E-05"
            ixy="-1.534865545378E-12"
            ixz="3.46424449605658E-10"
            iyy="4.98589881725446E-05"
            iyz="-5.64890953414983E-17"
            izz="2.130463008359E-05" />
      </inertial>
      <visual>
        <origin
            xyz="0 0 0"
            rpy="0 0 0" />
        <geometry>
          <mesh filename="package://${MESH_LINK_5}" />
        </geometry>
      </visual>
      <collision>
        <origin
            xyz="0 0 0"
            rpy="0 0 0" />
        <geometry>
          <mesh filename="package://${MESH_LINK_5}" />
        </geometry>
      </collision>
    </link>
    <link name="${prefix}mg400_end_effector_flange">
      <inertial>
        <origin
            xyz="0 0 5.0e-3"
            rpy="0 0 0" />
        <mass value="24.0e-3" />
        <inertia
            ixx="2.058e-6"
            ixy="0.0"
            ixz="0.0"
            iyy="2.058e-6"
            iyz="0.0"
            izz="3.335e-6" />
      </inertial>
      <visual>
        <origin
            xyz="0 0 0"
            rpy="0 0 0" />
        <geometry>
          <mesh filename="package://${MESH_FLANGE}" />
        </geometry>
      </visual>
      <collision>
        <origin
            xyz="0 0 0"
            rpy="0 0 0" />
        <geometry>
          <mesh filename="package://${MESH_FLANGE}" />
        </geometry>
      </collision>
    </link>
    <xacro:if value="${workspace_visible}">
      <link name="${prefix}mg400_workspace">
        <visual>
          <origin
              xyz="0 0 0"
              rpy="0 0 0" />
          <geometry>
            <mesh filename="package://${MESH_WORKSPACE}" />
          </geometry>
          <material name="${prefix}mg400_workspace_material" />
        </visual>
      </link>
    </xacro:if>

    <!-- joints -->
    <joint
        name="${prefix}mg400_base_joint"
        type="fixed">
      <parent link="${parent}" />
      <child link="${prefix}mg400_base_link" />
      <xacro:insert_block name="origin" />
    </joint>
    <xacro:if value="${workspace_visible}">
      <joint
          name="${prefix}workspace_joint"
          type="fixed">
        <origin
            xyz="-0.005 0 0.228"
            rpy="0 0 0" />
        <parent link="${prefix}mg400_base_link" />
        <child link="${prefix}mg400_workspace" />
      </joint>
    </xacro:if>

    <joint
        name="${prefix}mg400_j0"
        type="fixed">
      <origin
          xyz="-0.005 0 0.224"
          rpy="0 0 0" />
      <parent link="${prefix}mg400_base_link" />
      <child link="${prefix}mg400_origin_link" />
    </joint>
    <joint
        name="${prefix}mg400_j1"
        type="revolute">
      <origin
          xyz="${-5.0 * const.SCALE_MM} 0 ${109 * const.SCALE_MM}"
          rpy="0 0 0" />
      <parent link="${prefix}mg400_base_link" />
      <child link="${prefix}mg400_link1" />
      <axis xyz="0 0 1" />
      <limit
          lower="${-180.0 * const.TO_RADIAN}"
          upper="${180.0 * const.TO_RADIAN}"
          effort="0"
          velocity="0" />
    </joint>
    <joint
        name="${prefix}mg400_j2_1"
        type="revolute">
      <origin
          xyz="0.0435 -0.035775 0.119"
          rpy="0 0 0" />
      <parent link="${prefix}mg400_link1" />
      <child link="${prefix}mg400_link2_1" />
      <axis xyz="0 1 0" />
      <limit
          lower="-3.14"
          upper="3.14"
          effort="0"
          velocity="0" />
    </joint>
    <joint
        name="${prefix}mg400_j2_2"
        type="revolute">
      <origin
          xyz="0.00452885682964267 -0.0305 0.141500000000001"
          rpy="0 0 0" />
      <parent link="${prefix}mg400_link1" />
      <child link="${prefix}mg400_link2_2" />
      <axis xyz="0 1 0" />
      <limit
          lower="-3.14"
          upper="3.14"
          effort="0"
          velocity="0" />
    </joint>
    <joint
        name="${prefix}mg400_j3_1"
        type="revolute">
      <origin
          xyz="-0.0010512570171516 0.0357748756218898 0.175001164344716"
          rpy="0 0 0" />
      <parent link="${prefix}mg400_link2_1" />
      <child link="${prefix}mg400_link3_1" />
      <axis xyz="0 1 0" />
      <limit
          lower="-3.14"
          upper="3.14"
          effort="0"
          velocity="0" />
    </joint>
    <joint
        name="${prefix}mg400_j3_2"
        type="revolute">
      <origin
          xyz="-0.00105 0.0065 0.175"
          rpy="0 0 0" />
      <parent link="${prefix}mg400_link2_2" />
      <child link="${prefix}mg400_link3_2" />
      <axis xyz="0 1 0" />
      <limit
          lower="-3.14"
          upper="3.14"
          effort="0"
          velocity="0" />
    </joint>
    <joint
        name="${prefix}mg400_j4_1"
        type="revolute">
      <origin
          xyz="0.175 -0.017 0.00325"
          rpy="0 0 0" />
      <parent link="${prefix}mg400_link3_1" />
      <child link="${prefix}mg400_link4_1" />
      <axis xyz="0 1 0" />
      <limit
          lower="-3.14"
          upper="3.14"
          effort="0"
          velocity="0" />
    </joint>
    <joint
        name="${prefix}mg400_j4_2"
        type="revolute">
      <origin
          xyz="0.0679 0.0005 0.011972"
          rpy="0 0 0" />
      <parent link="${prefix}mg400_link3_2" />
      <child link="${prefix}mg400_link4_2" />
      <axis xyz="0 1 0" />
      <limit
          lower="-3.14"
          upper="3.14"
          effort="0"
          velocity="0" />
    </joint>
    <joint
        name="${prefix}mg400_j4_3"
        type="fixed">
      <origin
          xyz="0 0 ${2 * const.SCALE_MM}"
          rpy="0 0 0" />
      <parent link="${prefix}mg400_link5" />
      <child link="${prefix}mg400_link4_3" />
    </joint>
    <joint
        name="${prefix}mg400_j5_1"
        type="fixed">
      <origin
          xyz="0.066 0.017 0.031"
          rpy="0 0 0" />
      <parent link="${prefix}mg400_link4_1" />
      <child link="${prefix}mg400_link5" />
    </joint>
    <joint
        name="${prefix}mg400_j5"
        type="revolute">
      <origin
          xyz="0 0 ${(-70.0 - 14.0) * const.SCALE_MM}"
          rpy="0 0 0" />
      <parent link="${prefix}mg400_link5" />
      <child link="${prefix}mg400_end_effector_flange" />
      <axis xyz="0 0 1" />
      <limit
          lower="${-180.0 * const.TO_RADIAN}"
          upper="${180.0 * const.TO_RADIAN}"
          effort="0"
          velocity="0" />
    </joint>
  </xacro:macro>
</robot>